<?xml version="1.0" ?>
<!--
  Ignition Gazebo skid steer differential drive plugin demo

  Try sending commands:

    ign topic -t "/model/vehicle_blue/cmd_vel" -m ignition.msgs.Twist -p "linear: {x: 0.5}, angular: {z: 0.05}"

  Listen to odometry:

    ign topic -e -t /model/vehicle_blue/odometry

-->
<sdf version="1.6">
  <world name="tarkbot_model_v4">

    <physics name="1ms" type="ignored">
      <max_step_size>0.001</max_step_size>
      <real_time_factor>1.0</real_time_factor>
    </physics>
    <plugin
      filename="ignition-gazebo-physics-system"
      name="gz::sim::systems::Physics">
    </plugin>
    <plugin
      filename="libignition-gazebo-sensors-system.so"
      name="ignition::gazebo::systems::Sensors">
      <render_engine>ogre2</render_engine>
    </plugin>
    <plugin
      filename="ignition-gazebo-user-commands-system"
      name="gz::sim::systems::UserCommands">
    </plugin>
    <plugin
      filename="ignition-gazebo-scene-broadcaster-system"
      name="gz::sim::systems::SceneBroadcaster">
    </plugin>
    <plugin filename="VisualizeLidar" name="Visualize Lidar">
    </plugin>

    <plugin filename="libignition-gazebo-imu-system.so"
        name="ignition::gazebo::systems::Imu">
    </plugin> 

    <light type="directional" name="sun">
      <cast_shadows>true</cast_shadows>
      <pose>0 0 10 0 0 0</pose>
      <diffuse>1 1 1 1</diffuse>
      <specular>0.5 0.5 0.5 1</specular>
      <attenuation>
        <range>1000</range>
        <constant>0.9</constant>
        <linear>0.01</linear>
        <quadratic>0.001</quadratic>
      </attenuation>
      <direction>-0.5 0.1 -0.9</direction>
    </light>

  <gui fullscreen="0">
      <!-- 3D scene -->
      <plugin filename="GzScene3D" name="3D View">
        <ignition-gui>
          <title>3D View</title>
          <property type="bool" key="showTitleBar">false</property>
          <property type="string" key="state">docked</property>
        </ignition-gui>
        <engine>ogre2</engine>
        <scene>scene</scene>
        <ambient_light>0.7 0.7 0.7</ambient_light>
        <background_color>0.8 0.8 0.8</background_color>
        <camera_pose>1 1 1 0 0.5 3.92</camera_pose>
      </plugin>
      <!-- World control -->
      <plugin filename="WorldControl" name="World control">
        <ignition-gui>
          <title>World control</title>
          <property type="bool" key="showTitleBar">false</property>
          <property type="bool" key="resizable">false</property>
          <property type="double" key="height">72</property>
          <property type="double" key="width">121</property>
          <property type="double" key="z">1</property>
          <property type="string" key="state">floating</property>
          <anchors target="3D View">
            <line own="left" target="left"/>
            <line own="bottom" target="bottom"/>
          </anchors>
        </ignition-gui>
        <play_pause>true</play_pause>
        <step>true</step>
        <start_paused>true</start_paused>
        <service>/world/diff_bot/control</service>
        <stats_topic>/world/diff_bot/stats</stats_topic>
      </plugin>
      <!-- World statistics -->
      <plugin filename="WorldStats" name="World stats">
        <ignition-gui>
          <title>World stats</title>
          <property type="bool" key="showTitleBar">false</property>
          <property type="bool" key="resizable">false</property>
          <property type="double" key="height">110</property>
          <property type="double" key="width">290</property>
          <property type="double" key="z">1</property>
          <property type="string" key="state">floating</property>
          <anchors target="3D View">
            <line own="right" target="right"/>
            <line own="bottom" target="bottom"/>
          </anchors>
        </ignition-gui>
        <sim_time>true</sim_time>
        <real_time>true</real_time>
        <real_time_factor>true</real_time_factor>
        <iterations>true</iterations>
      </plugin>
      <!-- Image display -->
      
      <!-- Key publisher -->
      <plugin filename="KeyPublisher" name="Key Publisher">
        <ignition-gui>
          <title>Key publisher</title>
          <property type="bool" key="showTitleBar">false</property>
          <property type="bool" key="resizable">false</property>
          <property type="string" key="state">floating</property>
        </ignition-gui>
      </plugin>
    </gui>




    <model name="ground_plane">
      <static>true</static>
      <link name="link">
        <collision name="collision">
          <geometry>
            <plane>
              <normal>0 0 1</normal>
              <size>100 100</size>
            </plane>
          </geometry>
          <surface>
            <friction>
              <ode>
                <mu>50</mu>
              </ode>
            </friction>
          </surface>
        </collision>
        <visual name="visual">
          <geometry>
            <plane>
              <normal>0 0 1</normal>
              <size>100 100</size>
            </plane>
          </geometry>
          <material>
            <ambient>0.8 0.8 0.8 1</ambient>
            <diffuse>0.8 0.8 0.8 1</diffuse>
            <specular>0.8 0.8 0.8 1</specular>
          </material>
        </visual>
      </link>
    </model>

    <model name='tarkbot_model_v4'>
      <pose>0 -2 0.325 0 -0 0</pose>
    <link name='base_link'>
      <inertial>
        <pose>0.003841 -0.000112 0.001514 0 -0 0</pose>
        <mass>1.3</mass>
        <inertia>
          <ixx>0.00055851</ixx>
          <ixy>-2.2359e-07</ixy>
          <ixz>-3.9351e-07</ixz>
          <iyy>0.0011421</iyy>
          <iyz>1.0586e-07</iyz>
          <izz>0.0016527</izz>
        </inertia>
      </inertial>
      
      <collision name='base_link_collision'>
        <pose>0 0 0 0 -0 0</pose>
        <geometry>
          <mesh>
            <scale>1 1 1</scale>
            <uri>/home/fuzailx/fyp_ws/src/tarkbot_model_v4/meshes/base_link.STL</uri>
          </mesh>
        </geometry>
      </collision>
      <visual name='base_link_visual'>
        <pose>0 0 0 0 -0 0</pose>
        <geometry>
          <mesh>
            <scale>1 1 1</scale>
            <uri>/home/fuzailx/fyp_ws/src/tarkbot_model_v4/meshes/base_link.STL</uri>
          </mesh>
        </geometry>
        <material>
            <ambient>0.44 0.44 0.44 1</ambient>
            <diffuse>0.44 0.44 0.44 1</diffuse>
            <specular>0.44 0.44 0.44 1</specular>
        </material>
      </visual>

      <sensor name="imu_sensor" type="imu">
        <always_on>1</always_on>
        <update_rate>50</update_rate>
        <visualize>false</visualize>
        <topic>/model/tarkbot_model_v4/imu</topic>
        <imu>
        <angular_velocity>
          <x>
            <noise type="gaussian">
              <mean>0.0</mean>
              <stddev>0.1</stddev>
            </noise>
          </x>
          <y>
            <noise type="gaussian">
              <mean>0.0</mean>
              <stddev>0.1</stddev>
            </noise>
          </y>
          <z>
            <noise type="gaussian">
              <mean>0.0</mean>
              <stddev>0.2</stddev>
            </noise>
          </z>
        </angular_velocity>
        <linear_acceleration>
          <x>
            <noise type="gaussian">
              <mean>0.0</mean>
              <stddev>0.1</stddev>
            </noise>
          </x>
          <y>
            <noise type="gaussian">
              <mean>0.0</mean>
              <stddev>0.1</stddev>
            </noise>
          </y>
          <z>
            <noise type="gaussian">
              <mean>0.0</mean>
              <stddev>0.2</stddev>
            </noise>
          </z>
        </linear_acceleration>
      </imu>
      </sensor>
    </link>

    <joint name='front_left_joint' type='revolute'>
      <pose relative_to='base_link'>0.084 0.0777 -0.0145 0 -0 0</pose>
      <parent>base_link</parent>
      <child>front_left_wheel</child>
      <axis>
        <xyz>0 1 0</xyz>
        <limit>
          <effort>1</effort>
          <velocity>40</velocity>
          <lower>-1e+16</lower>
          <upper>1e+16</upper>
        </limit>
        <dynamics>
          <spring_reference>0</spring_reference>
          <spring_stiffness>0</spring_stiffness>
        </dynamics>
      </axis>
    </joint>
    <link name='front_left_wheel'>
      <pose relative_to='front_left_joint'>0 0 0 0 -0 0</pose>
      <inertial>
        <pose>0 0.022737 0 0 -0 0</pose>
        <mass>0.25253</mass>
        <inertia>
          <ixx>0.00020889</ixx>
          <ixy>2.9924e-10</ixy>
          <ixz>8.7397e-11</ixz>
          <iyy>0.0003594</iyy>
          <iyz>8.9988e-11</iyz>
          <izz>0.00020889</izz>
        </inertia>
      </inertial>
      <collision name='front_left_wheel_collision'>
        <pose>0 0 0 0 -0 0</pose>
        <geometry>
          <mesh>
            <scale>1 1 1</scale>
            <uri>/home/fuzailx/fyp_ws/src/tarkbot_model_v4/meshes/front_left_wheel.STL</uri>
          </mesh>
        </geometry>
      </collision>
      <visual name='front_left_wheel_visual'>
        <pose>0 0 0 0 -0 0</pose>
        <geometry>
          <mesh>
            <scale>1 1 1</scale>
            <uri>/home/fuzailx/fyp_ws/src/tarkbot_model_v4/meshes/front_left_wheel.STL</uri>
          </mesh>
        </geometry>
        <material>
            <ambient>0.17 0.17 0.17 1</ambient>
            <diffuse>0.17 0.17 0.17 1</diffuse>
            <specular>0.17 0.17 0.17 1</specular>
        </material>
      </visual>
    </link>
    <joint name='front_right_joint' type='revolute'>
      <pose relative_to='base_link'>0.084 -0.088718 -0.0145 0 -0 0</pose>
      <parent>base_link</parent>
      <child>front_right_wheel</child>
      <axis>
        <xyz>0 1 0</xyz>
        <limit>
          <effort>1</effort>
          <velocity>40</velocity>
          <lower>-1e+16</lower>
          <upper>1e+16</upper>
        </limit>
        <dynamics>
          <spring_reference>0</spring_reference>
          <spring_stiffness>0</spring_stiffness>
        </dynamics>
      </axis>
    </joint>
    <link name='front_right_wheel'>
      <pose relative_to='front_right_joint'>0 0 0 0 -0 0</pose>
      <inertial>
        <pose>-0 -0.011718 -0 0 -0 0</pose>
        <mass>0.25253</mass>
        <inertia>
          <ixx>0.00020889</ixx>
          <ixy>2.1458e-10</ixy>
          <ixz>1.582e-10</ixz>
          <iyy>0.0003594</iyy>
          <iyz>2.2715e-10</iyz>
          <izz>0.00020889</izz>
        </inertia>
      </inertial>
      <collision name='front_right_wheel_collision'>
        <pose>0 0 0 0 -0 0</pose>
        <geometry>
          <mesh>
            <scale>1 1 1</scale>
            <uri>/home/fuzailx/fyp_ws/src/tarkbot_model_v4/meshes/front_right_wheel.STL</uri>
          </mesh>
        </geometry>
      </collision>
      <visual name='front_right_wheel_visual'>
        <pose>0 0 0 0 -0 0</pose>
        <geometry>
          <mesh>
            <scale>1 1 1</scale>
            <uri>/home/fuzailx/fyp_ws/src/tarkbot_model_v4/meshes/front_right_wheel.STL</uri>
          </mesh>
        </geometry>
        <material>
            <ambient>0.17 0.17 0.17 1</ambient>
            <diffuse>0.17 0.17 0.17 1</diffuse>
            <specular>0.17 0.17 0.17 1</specular>
        </material>
      </visual>
    </link>
    <joint name='rear_left_joint' type='revolute'>
      <pose relative_to='base_link'>-0.084 0.0777 -0.0145 0 -0 0</pose>
      <parent>base_link</parent>
      <child>rear_left_wheel</child>
      <axis>
        <xyz>0 1 0</xyz>
        <limit>
          <effort>1</effort>
          <velocity>40</velocity>
          <lower>-1e+16</lower>
          <upper>1e+16</upper>
        </limit>
        <dynamics>
          <spring_reference>0</spring_reference>
          <spring_stiffness>0</spring_stiffness>
        </dynamics>
      </axis>
    </joint>
    <link name='rear_left_wheel'>
      <pose relative_to='rear_left_joint'>0 0 0 0 -0 0</pose>
      <inertial>
        <pose>0 0.022737 -0 0 -0 0</pose>
        <mass>0.25253</mass>
        <inertia>
          <ixx>0.00020889</ixx>
          <ixy>2.1843e-10</ixy>
          <ixz>-1.5841e-10</ixz>
          <iyy>0.0003594</iyy>
          <iyz>-2.2346e-10</iyz>
          <izz>0.00020889</izz>
        </inertia>
      </inertial>
      <collision name='rear_left_wheel_collision'>
        <pose>0 0 0 0 -0 0</pose>
        <geometry>
          <mesh>
            <scale>1 1 1</scale>
            <uri>/home/fuzailx/fyp_ws/src/tarkbot_model_v4/meshes/rear_left_wheel.STL</uri>
          </mesh>
        </geometry>
      </collision>
      <visual name='rear_left_wheel_visual'>
        <pose>0 0 0 0 -0 0</pose>
        <geometry>
          <mesh>
            <scale>1 1 1</scale>
            <uri>/home/fuzailx/fyp_ws/src/tarkbot_model_v4/meshes/rear_left_wheel.STL</uri>
          </mesh>
        </geometry>
        <material>
            <ambient>0.17 0.17 0.17 1</ambient>
            <diffuse>0.17 0.17 0.17 1</diffuse>
            <specular>0.17 0.17 0.17 1</specular>
        </material>
      </visual>
    </link>
    <joint name='rear_right_joint' type='revolute'>
      <pose relative_to='base_link'>-0.084 -0.088718 -0.0145 0 -0 0</pose>
      <parent>base_link</parent>
      <child>rear_right_wheel</child>
      <axis>
        <xyz>0 1 0</xyz>
        <limit>
          <effort>1</effort>
          <velocity>40</velocity>
          <lower>-1e+16</lower>
          <upper>1e+16</upper>
        </limit>
        <dynamics>
          <spring_reference>0</spring_reference>
          <spring_stiffness>0</spring_stiffness>
        </dynamics>
      </axis>
    </joint>
    <link name='rear_right_wheel'>
      <pose relative_to='rear_right_joint'>0 0 0 0 -0 0</pose>
      <inertial>
        <pose>-0 -0.011718 -0 0 -0 0</pose>
        <mass>0.25253</mass>
        <inertia>
          <ixx>0.00020889</ixx>
          <ixy>1.9412e-10</ixy>
          <ixz>1.5427e-10</ixz>
          <iyy>0.0003594</iyy>
          <iyz>2.4486e-10</iyz>
          <izz>0.00020889</izz>
        </inertia>
      </inertial>
      <collision name='rear_right_wheel_collision'>
        <pose>0 0 0 0 -0 0</pose>
        <geometry>
          <mesh>
            <scale>1 1 1</scale>
            <uri>/home/fuzailx/fyp_ws/src/tarkbot_model_v4/meshes/rear_right_wheel.STL</uri>
          </mesh>   
        </geometry>
      </collision>
      <visual name='rear_right_wheel_visual'>
        <pose>0 0 0 0 -0 0</pose>
        <geometry>
          <mesh>
            <scale>1 1 1</scale>
            <uri>/home/fuzailx/fyp_ws/src/tarkbot_model_v4/meshes/rear_right_wheel.STL</uri>
          </mesh>
        </geometry>
        <material>
            <ambient>0.17 0.17 0.17 1</ambient>
            <diffuse>0.17 0.17 0.17 1</diffuse>
            <specular>0.17 0.17 0.17 1</specular>
        </material>
      </visual>
    </link>
    <link name="lidar_link">
            <pose>0 0 0.08 0 0 0</pose>
            <inertial>
              <mass>0.1</mass>
              <inertia>
                <ixx>0.000166667</ixx>
                <iyy>0.000166667</iyy>
                <izz>0.000166667</izz>
              </inertia>
            </inertial>
            <collision name="collision">
              <geometry>
                <box>
                  <size>0.1 0.1 0.1</size>
                </box>
              </geometry>
            </collision>
            <visual name="visual">
              <geometry>
                <cylinder>
                  <length> 0.06 </length>
                  <radius> 0.05 </radius>
                </cylinder>
              </geometry>
              <material>
                <ambient>0.1 0.2 0.2 1</ambient>
                <diffuse>0.1 0.2 0.2 1</diffuse>
                <specular>0.1 0.2 0.2 1</specular>
              </material>
            </visual>
            <sensor name='gpu_lidar' type='gpu_lidar'>
            <pose>0 0 0 0 0 0</pose>
              <topic>lidar</topic>
              <update_rate>10</update_rate>
              <lidar>
                <scan>
                  <horizontal>
                    <samples>640</samples>
                    <resolution>1</resolution>
                    <min_angle>-3.14</min_angle>
                    <max_angle>3.14</max_angle>
                  </horizontal>
                  <vertical>
                    <samples>16</samples>
                    <resolution>1</resolution>
                    <min_angle>-0.25</min_angle>
                    <max_angle>0.25</max_angle>
                  </vertical>
                </scan>
                <range>
                  <min>0.08</min>
                  <max>10.0</max>
                  <resolution>0.01</resolution>
                </range>
              </lidar>
              <alwaysOn>1</alwaysOn>
              <visualize>true</visualize>
            </sensor>
          </link>


    <joint name='lidar_sensor_joint' type='fixed'>
      <parent>base_link</parent>
      <child>lidar_link</child>
    </joint>

    <joint name='camera_sensor_joint' type='fixed'>
      <parent>base_link</parent>
      <child>camera</child>
    </joint>

    <plugin
        filename="ignition-gazebo-diff-drive-system"
        name="gz::sim::systems::DiffDrive">
        <left_joint>front_left_joint</left_joint>
        <left_joint>rear_left_joint</left_joint>
        <right_joint>front_right_joint</right_joint>
        <right_joint>rear_right_joint</right_joint>
        <wheel_separation>0.168</wheel_separation>
        <wheel_radius>0.05</wheel_radius>
      </plugin>


    <link name="camera">
        <pose>-0.15 0.0 0.2 0 0 0</pose>
        <inertial>
          <mass>0.1</mass>
          <inertia>
            <ixx>0.000166667</ixx>
            <iyy>0.000166667</iyy>
            <izz>0.000166667</izz>
          </inertia>
        </inertial>
        <collision name="collision">
          <geometry>
            <box>
              <size>0.01 0.01 0.01</size>
            </box>
          </geometry>
        </collision>
        <visual name="visual">
          <geometry>
            <box>
              <size>0.01 0.01 0.01</size>
            </box>
          </geometry>
          <material>
                <ambient>0.1 0.1 0.4 1</ambient>
                <diffuse>0.1 0.1 0.4 1</diffuse>
                <specular>0.1 0.1 0.4 1</specular>
          </material>
        </visual>
        <sensor name="camera" type="camera">
          <camera>
            <horizontal_fov>1.047</horizontal_fov>
            <image>
              <width>1280</width>
              <height>720</height>
            </image>
            <clip>
              <near>0.1</near>
              <far>100</far>
            </clip>
          </camera>
          <always_on>1</always_on>
          <update_rate>30</update_rate>
          <visualize>true</visualize>
          <topic>camera</topic>
        </sensor>
      </link>
  </model>

    <include>
      <uri>https://fuel.gazebosim.org/1.0/nlamprian/models/Elevator</uri>
    </include>
    <include>
      <uri>/home/fuzailx/mulyi_floor_v2/model.sdf</uri>
    </include>
  
  
  </world>
</sdf>
